from odoo.tests import TransactionCase, tagged
from odoo.exceptions import ValidationError, MissingError


@tagged("res_partner", "bin", "-at_install", "post_install")
class TestResPartner(TransactionCase):
    def setUp(self):
        super().setUp()
        self.company = self.env.ref("base.main_company")
        self.company.write({
            "validate_user_creation_by_company": True,
        })
        self.partner = self.env["res.partner"].create({
            "name": "Test Partner",
            "prefix_vat": "V",
            "vat": "27436422",
            "email": "test@example.com",
            "country_id": self.env.ref("base.ve").id,
        })

    def test_duplicate_vat(self):
        with self.assertRaises(ValidationError):
            self.env["res.partner"].create({
                "name": "Another",
                "prefix_vat": "V",
                "vat": "27436422",
                "email": "other@example.com",
                "country_id": self.env.ref("base.ve").id,
            })

    def test_duplicate_email(self):
        with self.assertRaises(ValidationError):
            self.env["res.partner"].create({
                "name": "Other",
                "prefix_vat": "V",
                "vat": "12345678",
                "email": "test@example.com",
                "country_id": self.env.ref("base.ve").id,
            })

    def test_check_vat_invalid_characters(self):
        self.partner.vat = "12A34"
        with self.assertRaises(MissingError):
            self.partner._check_vat()

    def test_check_vat_valid(self):
        self.partner.vat = "123456"
        # Should not raise
        self.partner._check_vat()
